<?xml version="1.0" ?>
<!-- =================================================================================== -->
<!-- |    This document was autogenerated by xacro from /home/recs/ros2_ws/src/e100_description/urdf/ria_e100.urdf.xacro | -->
<!-- |    EDITING THIS FILE BY HAND IS NOT RECOMMENDED                                 | -->
<!-- =================================================================================== -->
<robot name="RIA-E100">
  <material name="Dark_Grey">
    <color rgba="0.2 0.2 0.2 1"/>
  </material>
  <material name="Army_Green">
    <color rgba="0.4235 0.4862 0.3490 1"/>
  </material>
  <material name="Black">
    <color rgba="0 0 0 1"/>
  </material>
  <material name="Red">
    <color rgba="1 0 0 1"/>
  </material>
  <material name="Green">
    <color rgba="0 1 0 1"/>
  </material>
  <link name="front_left_wheel">
    <inertial>
      <mass value="3.2"/>
      <origin rpy="0 0 0" xyz="0 0.53972 0"/>
      <inertia ixx="0.00754455" ixy="0.0" ixz="0.0" iyy="0.0134055" iyz="0.0" izz="0.00754449"/>
    </inertial>
    <visual>
      <geometry>
        <mesh filename="package://e100_description/meshes/driven_wheel.stl"/>
      </geometry>
      <material name="Dark_Grey"/>
      <origin rpy="0 0 0" xyz="0 0.53972 0"/>
    </visual>
    <collision>
      <geometry>
        <cylinder length="0.047" radius="0.099"/>
      </geometry>
      <origin rpy="1.5707963267948966 0.0 0.0" xyz="0.0 0.0 0.0"/>
    </collision>
  </link>
  <link name="front_right_wheel">
    <inertial>
      <mass value="3.2"/>
      <origin rpy="0 0 0" xyz="0 -0.26986 0"/>
      <inertia ixx="0.00754455" ixy="0.0" ixz="0.0" iyy="0.0134055" iyz="0.0" izz="0.00754449"/>
    </inertial>
    <visual>
      <geometry>
        <mesh filename="package://e100_description/meshes/driven_wheel.stl"/>
      </geometry>
      <material name="Dark_Grey"/>
      <origin rpy="0 0 0" xyz="0 -0.26986 0"/>
    </visual>
    <collision>
      <geometry>
        <cylinder length="0.047" radius="0.099"/>
      </geometry>
      <origin rpy="1.5707963267948966 0.0 0.0" xyz="0.0 0.0 0.0"/>
    </collision>
  </link>
  <link name="rear_left_wheel">
    <inertial>
      <mass value="0.51102761"/>
      <origin rpy="0 0 0" xyz="-0.01869970 -1.463E-05 -0.03693169"/>
      <inertia ixx="2.6625E-04" ixy="-9E-08" ixz="8.923E-05" iyy="3.6501E-04" iyz="0.0" izz="1.9203E-04"/>
    </inertial>
    <visual>
      <geometry>
        <mesh filename="package://e100_description/meshes/omni_wheel.stl"/>
      </geometry>
      <material name="Dark_Grey"/>
      <origin rpy="0 0 0" xyz="0 0 0"/>
    </visual>
    <collision>
      <geometry>
        <mesh filename="package://e100_description/meshes/omni_wheel.stl"/>
      </geometry>
      <origin rpy="0 0 0" xyz="0 0 0"/>
    </collision>
  </link>
  <link name="rear_right_wheel">
    <inertial>
      <mass value="0.51102761"/>
      <origin rpy="0 0 0" xyz="-0.01869970 -1.463E-05 -0.03693169"/>
      <inertia ixx="2.6625E-04" ixy="-9E-08" ixz="8.923E-05" iyy="3.6501E-04" iyz="0.0" izz="1.9203E-04"/>
    </inertial>
    <visual>
      <geometry>
        <mesh filename="package://e100_description/meshes/omni_wheel.stl"/>
      </geometry>
      <material name="Dark_Grey"/>
      <origin rpy="0 0 0" xyz="0 0 0"/>
    </visual>
    <collision>
      <geometry>
        <mesh filename="package://e100_description/meshes/omni_wheel.stl"/>
      </geometry>
      <origin rpy="0 0 0" xyz="0 0 0"/>
    </collision>
  </link>
  <!-- source en.wikipedia.org/wiki/List_of_moments_of_inertia-->
  <!-- This file unifies all sensors that can be used on simulation, defined as xacro:macros -->
  <!-- Includes -->
  <link name="base_link">
    <visual>
      <geometry>
        <box size="0.001 0.001 0.001"/>
      </geometry>
      <material name="Green"/>
      <origin rpy="0 0 0" xyz="0 0 0"/>
    </visual>
  </link>
  <link name="RIA_BASE">
    <inertial>
      <mass value="7.84422145"/>
      <origin rpy=" 0 0 0" xyz="0.00729794 0.00167026 0.05375158"/>
      <inertia ixx="0.13537085" ixy="-3.0694E-04" ixz="0.00230818" iyy="0.22927569" iyz="3.874E-05" izz="0.30459422"/>
    </inertial>
    <visual>
      <geometry>
        <mesh filename="package://e100_description/meshes/base.stl"/>
      </geometry>
      <material name="Dark_Grey"/>
      <origin rpy="0 0 0" xyz="0 0 0"/>
    </visual>
    <collision>
      <geometry>
        <mesh filename="package://e100_description/meshes/base.stl"/>
      </geometry>
      <origin rpy="0 0 0" xyz="0 0 0"/>
    </collision>
  </link>
  <link name="RIA_TOP_FRAME">
    <inertial>
      <mass value="6.03381"/>
      <origin rpy=" 0 0 0" xyz="0.006450 -2.594E-5 -0.0538955"/>
      <inertia ixx="0.08424958" ixy="3.313E-05" ixz="0.00167397" iyy="0.13408855" iyz="-7.97E-06" izz="0.18770025"/>
    </inertial>
    <visual>
      <geometry>
        <mesh filename="package://e100_description/meshes/top_plate.stl"/>
      </geometry>
      <material name="Dark_Grey"/>
      <origin rpy="0 0 0" xyz="0 0 0"/>
    </visual>
    <collision>
      <geometry>
        <mesh filename="package://e100_description/meshes/top_plate.stl"/>
      </geometry>
      <origin rpy="0 0 0" xyz="0 0 0"/>
    </collision>
  </link>
  <joint name="base_link_to_RIA_BASE" type="fixed">
    <parent link="base_link"/>
    <child link="RIA_BASE"/>
    <origin rpy="0 0 0" xyz="-0.136 0 0"/>
  </joint>
  <joint name="RIA_BASE_to_RIA_TOP_FRAME" type="fixed">
    <parent link="RIA_BASE"/>
    <child link="RIA_TOP_FRAME"/>
    <origin rpy="0 0 0" xyz="0 0 0.265"/>
  </joint>
  <joint name="front_right_wheel_joint" type="continuous">
    <parent link="RIA_BASE"/>
    <child link="front_right_wheel"/>
    <origin rpy="3.141592653589793 0 0" xyz=" 0.136 0.227 0.027 "/>
    <axis rpy="0 0 0" xyz="0 1 0"/>
    <limit effort="200" velocity="200"/>
    <joint_properties damping="0" friction="0"/>
  </joint>
  <joint name="front_left_wheel_joint" type="continuous">
    <parent link="RIA_BASE"/>
    <child link="front_left_wheel"/>
    <origin rpy="0 0 0" xyz="0.136 -0.227 0.027"/>
    <axis rpy="0 0 0" xyz="0 1 0"/>
    <limit effort="200" velocity="200"/>
    <joint_properties damping="0" friction="0"/>
  </joint>
  <joint name="rear_left_wheel_joint" type="fixed">
    <parent link="RIA_BASE"/>
    <child link="rear_left_wheel"/>
    <origin rpy="0 0 0" xyz="-0.18923 0.115 0.0005"/>
  </joint>
  <joint name="rear_right_wheel_joint" type="fixed">
    <parent link="RIA_BASE"/>
    <child link="rear_right_wheel"/>
    <origin rpy="0 0 0" xyz="-0.18923 -0.115 0.0005"/>
  </joint>
  <joint name="imu_joint" type="fixed">
    <!--axis xyz="1 0 0"/-->
    <!--origin xyz="0 0 0.2825"/-->
    <origin rpy="0 0 0" xyz="0 -0.12 0.1"/>
    <parent link="base_link"/>
    <child link="imu_link"/>
  </joint>
  <link name="imu_link">
    <inertial>
      <origin rpy="0 0 0" xyz="0.0 0 0.01"/>
      <mass value="0.005"/>
      <inertia ixx="8.333333333333334e-10" ixy="0" ixz="0" iyy="8.333333333333334e-10" iyz="0" izz="8.333333333333334e-10"/>
    </inertial>
    <visual>
      <origin rpy="0 0 0" xyz="0 0 0"/>
      <geometry>
        <box size="0.001 0.001 0.001"/>
      </geometry>
    </visual>
    <!--collision>
	        <origin rpy="0 0 0" xyz="0 0 0"/>
	        <geometry>
	          <box size="0.001 0.001 0.001"/>
	        </geometry>
	      </collision-->
  </link>
  <!--<gazebo>-->
  <!--<plugin name="${prefix}_controller" filename="libgazebo_ros_imu.so">-->
  <!--<topicName>${ns}imu/data</topicName>-->
  <!--<serviceName>imu/service</serviceName>-->
  <!--<bodyName>${prefix}_link</bodyName>-->
  <!--<updateRateHZ>50.0</updateRateHZ>-->
  <!--<gaussianNoise>0.0</gaussianNoise>-->
  <!--</plugin>-->
  <!--</gazebo>-->
  <gazebo reference="imu_link">
    <gravity>true</gravity>
    <sensor name="imu_imu_sensor" type="imu">
      <always_on>true</always_on>
      <update_rate>100</update_rate>
      <visualize>true</visualize>
      <topic>__default_topic__</topic>
      <plugin filename="libgazebo_ros_imu_sensor.so" name="imu_imu_plugin">
        <topicName>e100_imu</topicName>
        <bodyName>imu_link</bodyName>
        <updateRateHZ>100.0</updateRateHZ>
        <gaussianNoise>0.0</gaussianNoise>
        <xyzOffset>0 0 0</xyzOffset>
        <rpyOffset>0 0 0</rpyOffset>
        <frameName>imu_link</frameName>
      </plugin>
      <pose>0 0 0 0 0 0</pose>
    </sensor>
  </gazebo>
  <joint name="front_rgbd_camera_joint" type="fixed">
    <origin rpy="0 0 0" xyz="0.2004 0.0 -0.071"/>
    <parent link="RIA_TOP_FRAME"/>
    <child link="front_rgbd_camera_link"/>
  </joint>
  <link name="front_rgbd_camera_link">
    <visual>
      <origin rpy="0 0 0" xyz="0 0 0"/>
      <geometry>
        <mesh filename="package://gaitech_sensors/meshes/orbbec_astra.dae"/>
      </geometry>
    </visual>
    <collision>
      <geometry>
        <mesh filename="package://gaitech_sensors/meshes/orbbec_astra.dae"/>
      </geometry>
    </collision>
    <inertial>
      <mass value="0.001"/>
      <origin xyz="0.0 0.0 0.0"/>
      <inertia ixx="2.3437500000000006e-06" ixy="0" ixz="0" iyy="2.0833333333333336e-07" iyz="0" izz="2.4020833333333336e-06"/>
    </inertial>
  </link>
  <joint name="front_rgbd_camera_rgb_joint" type="fixed">
    <origin rpy="0.0 0.0 0.0" xyz="0.0 0.0125 0.0150"/>
    <parent link="front_rgbd_camera_link"/>
    <child link="front_rgbd_camera_rgb_frame"/>
  </joint>
  <link name="front_rgbd_camera_rgb_frame">
    <inertial>
      <mass value="0.297"/>
      <origin xyz="-0.02 -0.0125 0.0"/>
      <inertia ixx="0.0006960937500000001" ixy="0" ixz="0" iyy="6.1875e-05" iyz="0" izz="0.00071341875"/>
    </inertial>
  </link>
  <joint name="front_rgbd_camera_rgb_optical_joint" type="fixed">
    <origin rpy="-1.5707963267948966 0 -1.5707963267948966" xyz="0.0 0.0 0.0"/>
    <parent link="front_rgbd_camera_rgb_frame"/>
    <child link="front_rgbd_camera_rgb_optical_frame"/>
  </joint>
  <link name="front_rgbd_camera_rgb_optical_frame">
    <inertial>
      <mass value="0.001"/>
      <origin rpy="1.5707963267948966 0 1.5707963267948966" xyz="0 0 0"/>
      <inertia ixx="2.3437500000000006e-06" ixy="0" ixz="0" iyy="2.0833333333333336e-07" iyz="0" izz="2.4020833333333336e-06"/>
    </inertial>
  </link>
  <joint name="front_rgbd_camera_depth_joint" type="fixed">
    <origin rpy="0 0 0" xyz="0.0 0.0375 0.0150"/>
    <parent link="front_rgbd_camera_link"/>
    <child link="front_rgbd_camera_depth_frame"/>
  </joint>
  <link name="front_rgbd_camera_depth_frame">
    <inertial>
      <mass value="0.001"/>
      <origin xyz="0 0 0"/>
      <inertia ixx="2.3437500000000006e-06" ixy="0" ixz="0" iyy="2.0833333333333336e-07" iyz="0" izz="2.4020833333333336e-06"/>
    </inertial>
  </link>
  <joint name="front_rgbd_camera_depth_optical_joint" type="fixed">
    <origin rpy="-1.5707963267948966 0 -1.5707963267948966" xyz="0 0 0"/>
    <parent link="front_rgbd_camera_depth_frame"/>
    <child link="front_rgbd_camera_depth_optical_frame"/>
  </joint>
  <link name="front_rgbd_camera_depth_optical_frame">
    <inertial>
      <mass value="0.001"/>
      <origin xyz="0 0 0"/>
      <inertia ixx="2.3437500000000006e-06" ixy="0" ixz="0" iyy="2.0833333333333336e-07" iyz="0" izz="2.4020833333333336e-06"/>
    </inertial>
  </link>
  <gazebo reference="front_rgbd_camera_link">
    <sensor name="front_rgbd_camera_depth_sensor" type="depth">
      <always_on>true</always_on>
      <update_rate>20.0</update_rate>
      <camera>
        <horizontal_fov>1.0471975511965976</horizontal_fov>
        <image>
          <format>R8G8B8</format>
          <width>640</width>
          <height>480</height>
        </image>
        <clip>
          <near>0.05</near>
          <far>3.5</far>
        </clip>
      </camera>
      <plugin filename="libgazebo_ros_openni_kinect.so" name="front_rgbd_camera_controller">
        <cameraName>front_rgbd_camera</cameraName>
        <alwaysOn>true</alwaysOn>
        <updateRate>10</updateRate>
        <imageTopicName>rgb/image_raw</imageTopicName>
        <depthImageTopicName>depth/image_raw</depthImageTopicName>
        <pointCloudTopicName>depth/points</pointCloudTopicName>
        <cameraInfoTopicName>rgb/camera_info</cameraInfoTopicName>
        <depthImageCameraInfoTopicName>depth/camera_info</depthImageCameraInfoTopicName>
        <frameName>/front_rgbd_camera_depth_optical_frame</frameName>
        <baseline>0.1</baseline>
        <distortion_k1>0.0</distortion_k1>
        <distortion_k2>0.0</distortion_k2>
        <distortion_k3>0.0</distortion_k3>
        <distortion_t1>0.0</distortion_t1>
        <distortion_t2>0.0</distortion_t2>
        <pointCloudCutoff>0.4</pointCloudCutoff>
      </plugin>
    </sensor>
  </gazebo>
  <joint name="front_laser_base_joint" type="fixed">
    <origin rpy="0 0 0" xyz="0.167 0.0 0.0"/>
    <parent link="RIA_TOP_FRAME"/>
    <child link="front_laser_base_link"/>
  </joint>
  <link name="front_laser_base_link">
    <collision>
      <origin rpy="0 0 0" xyz="0 0 0"/>
      <geometry>
        <mesh filename="package://gaitech_sensors/meshes/rplidar_a2.dae"/>
      </geometry>
    </collision>
    <visual>
      <origin rpy="0 0 0" xyz="0 0 0"/>
      <geometry>
        <mesh filename="package://gaitech_sensors/meshes/rplidar_a2.dae"/>
      </geometry>
    </visual>
    <inertial>
      <mass value="0.190"/>
      <origin rpy="0 0 0" xyz="0 0 0.02040"/>
      <inertia ixx="0.00011708955833333335" ixy="0" ixz="0" iyy="0.00011708955833333335" iyz="0" izz="0.00018146551666666668"/>
    </inertial>
  </link>
  <joint name="front_laser_laser_joint" type="fixed">
    <origin rpy="0 0 3.1415" xyz="0 0 0.03086"/>
    <parent link="front_laser_base_link"/>
    <child link="front_laser_link"/>
  </joint>
  <link name="front_laser_link">
    </link>
  <gazebo reference="front_laser_link">
    <sensor name="front_laser_rplidar_a2_sensor" type="gpu_ray">
      <pose>0 0 0 0 0 0</pose>
      <visualize>false</visualize>
      <update_rate>10</update_rate>
      <ray>
        <scan>
          <horizontal>
            <samples>361</samples>
            <resolution>0.9</resolution>
            <min_angle>-3.14159</min_angle>
            <max_angle>3.14159</max_angle>
          </horizontal>
        </scan>
        <range>
          <min>0.15</min>
          <max>6.0</max>
          <resolution>0.0174</resolution>
        </range>
        <noise>
          <type>gaussian</type>
          <mean>0.0</mean>
          <stddev>0.01</stddev>
        </noise>
      </ray>
      <plugin filename="libgazebo_ros_gpu_laser.so" name="front_laser_controller">
        <topicName>front_laser/scan</topicName>
        <frameName>/front_laser_link</frameName>
      </plugin>
    </sensor>
  </gazebo>
</robot>
